Workbook
Name UPDATE: 'Data Sheet'!$E$1

Sheet Coverpage
B18: FINANCIAL MODELLING
B19: & VALUATION REPORT
B20: 2026
B25: Prepared By: Daksh
B37: DISCLAIMER : This Report has been prepared for education purposes only. All the information is sourced from publicly availabe data, and does not constitute investment advice.

Sheet Index
B3: TABLE OF CONTENTS
B7: 1 | C7: One Page Profile
B8: 2 | C8: Historical Financial statement
B9: 3 | C9: Ratio Analysis
B10: 4 | C10: Common Size Statement Analysis
B11: 5 | C11: Forecasting
B12: 6 | C12: Return on Market
B13: 7 | C13: Weighted Average cost of capital
B14: 8 | C14: Intrinsic Growth
B15: 9 | C15: Valuation - Discounted Cashflow
B16: 10 | C16: Valuation - Comparable Company (Relative)
B17: 11 | C17: Value at Risk
B18: 12 | C18: Football Field Analysis
... B20: 14 | C20: Altman's Z Score Analysis

Sheet One Pager
B2: ='Data Sheet'!B1& " - "&"One Page Profile" -> INFOSYS LTD - One Page Profile
C4: Infosys Limited is an Indian multinational technology company that offers information technology, business consulting, and outsourcing services. Founded in 1981 by seven engineers, the company is headquartered in Bengaluru and considered one of the Big Six Indian IT companies.Infosys offers Software development, maintenance, and the independent validation services across industries Such as finance, insurance, manufacturing and among others.
B6: INR(Crs.)
B7: Key Financial Metrics | D7: ='Historical FS'!$H$11 -> 44286 | E7: ='Historical FS'!$I$11 -> 44651 | F7: ='Historical FS'!$J$11 -> 45016 | G7: ='Historical FS'!$K$11 -> 45382 | H7: ='Historical FS'!$L$11 -> 45747 | J7: Share Price - 5 Years
B9: Total Sales | D9: ='Historical FS'!$H$14 -> 100472 | E9: ='Historical FS'!$H$14 -> 100472 | F9: ='Historical FS'!$H$14 -> 100472 | G9: ='Historical FS'!$H$14 -> 100472 | H9: ='Historical FS'!$H$14 -> 100472
B10: Sales Growth (Y-O-Y) | D10: ='Ratio Analysis'!H13 -> 0.10662951 | E10: ='Ratio Analysis'!I13 -> 0.21069552 | F10: ='Ratio Analysis'!J13 -> 0.20655864 | G10: ='Ratio Analysis'!K13 -> 0.047033734 | H10: ='Ratio Analysis'!L13 -> 0.060649444
B11: Gross Profit Margins (%) | D11: ='Ratio Analysis'!H19 -> 0.31831754 | E11: ='Ratio Analysis'!I19 -> 0.30271043 | F11: ='Ratio Analysis'!J19 -> 0.28539794 | G11: ='Ratio Analysis'!K19 -> 0.28398516 | H11: ='Ratio Analysis'!L19 -> 0.28471072
B12: EBITDA Margins (%) | D12: ='Ratio Analysis'!H20 -> 0.27757982 | E12: ='Ratio Analysis'!I20 -> 0.25888475 | F12: ='Ratio Analysis'!J20 -> 0.23935898 | G12: ='Ratio Analysis'!K20 -> 0.2370339 | H12: ='Ratio Analysis'!L20 -> 0.24072642
B13: EBIT Margins (%) | D13: ='Ratio Analysis'!H21 -> 0.2450633 | E13: ='Ratio Analysis'!I21 -> 0.23030886 | F13: ='Ratio Analysis'!J21 -> 0.21057186 | G13: ='Ratio Analysis'!K21 -> 0.20659205 | H13: ='Ratio Analysis'!L21 -> 0.21120314
B14: Net Margin (%) | D14: ='Ratio Analysis'!H23 -> 0.19331754 | E14: ='Ratio Analysis'!I23 -> 0.18206033 | F14: ='Ratio Analysis'!J23 -> 0.16426036 | G14: ='Ratio Analysis'!K23 -> 0.17080757 | H14: ='Ratio Analysis'!L23 -> 0.1641205
B15: Earning Per Share (In Rs.) | D15: ='Historical FS'!$H$52 -> 45.586406 | E15: ='Historical FS'!$H$52 -> 45.586406 | F15: ='Historical FS'!$H$52 -> 45.586406 | G15: ='Historical FS'!$H$52 -> 45.586406 | H15: ='Historical FS'!$H$52 -> 45.586406
B16: EPS Growth (Y-O-Y) | D16: ='Historical FS'!$H$53 -> 1.166852 | E16: ='Historical FS'!$H$53 -> 1.166852 | F16: ='Historical FS'!$H$53 -> 1.166852 | G16: ='Historical FS'!$H$53 -> 1.166852 | H16: ='Historical FS'!$H$53 -> 1.166852
B17: Dividend Per Share (in Rs.) | D17: ='Historical FS'!$H$55 -> 26.91952 | E17: ='Historical FS'!$H$55 -> 26.91952 | F17: ='Historical FS'!$H$55 -> 26.91952 | G17: ='Historical FS'!$H$55 -> 26.91952 | H17: ='Historical FS'!$H$55 -> 26.91952
B18: DPS Growth (Y-O-Y) | D18: ='Ratio Analysis'!H17 -> 0.54369512 | E18: ='Ratio Analysis'!I17 -> 0.14865158 | F18: ='Ratio Analysis'!J17 -> 0.096761529 | G18: ='Ratio Analysis'!K17 -> 0.35349861 | H18: ='Ratio Analysis'!L17 -> -0.064855345
B20: Key Financial Ratios | D20: ='Historical FS'!$H$11 -> 44286 | E20: ='Historical FS'!$I$11 -> 44651 | F20: ='Historical FS'!$J$11 -> 45016 | G20: ='Historical FS'!$K$11 -> 45382 | H20: ='Historical FS'!$L$11 -> 45747 | J20: Volume - 5 Years
B22: Price to Earning Ratio | D22: ='P&L'!G14 -> 30.121702 | E22: ='P&L'!H14 -> 36.280171 | F22: ='P&L'!I14 -> 24.585986 | G22: ='P&L'!J14 -> 23.703944 | H22: ='P&L'!K14 -> 24.420247
B23: EV/ EBITDA | D23: ='Data Sheet'!G101 -> 20.204958 | E23: ='Data Sheet'!H101 -> 25.091505 | F23: ='Data Sheet'!I101 -> 16.752785 | G23: ='Data Sheet'!J101 -> 16.894951 | H23: ='Data Sheet'!K101 -> 16.212409
B24: EV/ Sales | D24: ='Data Sheet'!G102 -> 5.6084886 | E24: ='Data Sheet'!H102 -> 6.4958081 | F24: ='Data Sheet'!I102 -> 4.0099296 | G24: ='Data Sheet'!J102 -> 4.0046761 | H24: ='Data Sheet'!K102 -> 3.9027552
B25: Price to Book Value | D25: ='Data Sheet'!G105 -> 7.634282 | E25: ='Data Sheet'!H105 -> 10.645715 | F25: ='Data Sheet'!I105 -> 7.8560258 | G25: ='Data Sheet'!J105 -> 7.0568974 | H25: ='Data Sheet'!K105 -> 6.8080952
B26: Return on Equity (%) | D26: ='Ratio Analysis'!H31 -> 0.25439091 | E26: ='Ratio Analysis'!I31 -> 0.29390843 | F26: ='Ratio Analysis'!J31 -> 0.31970507 | G26: ='Ratio Analysis'!K31 -> 0.29788007 | H26: ='Ratio Analysis'!L31 -> 0.2791751
B27: Return on Capital Employed (%) | D27: ='Ratio Analysis'!H29 -> 0.34145894 | E27: ='Ratio Analysis'!I29 -> 0.38962437 | F27: ='Ratio Analysis'!J29 -> 0.41968318 | G27: ='Ratio Analysis'!K29 -> 0.37755895 | H27: ='Ratio Analysis'!L29 -> 0.37710606
B29: Top 10 Shareholders | F29: Shares (in Crs.) | G29: Holding (%) | H29: Value (Crs.) | J29: Shareholding Pattern
B31: ='Raw CF'!D31 -> LIFE INSURANCE CORPORATION OF INDIA - ULIF00220091 | F31: ='Raw CF'!E31 -> 41.930862 | G31: ='Raw CF'!F31 -> 0.1128 | H31: ='Raw CF'!G31 -> 54405.293
B32: ='Raw CF'!D32 -> SBI MUTUAL FUND | F32: ='Raw CF'!E32 -> 17.329272 | G32: ='Raw CF'!F32 -> 0.0466 | H32: ='Raw CF'!G32 -> 22484.73
B33: ='Raw CF'!D33 -> ICICI PRUDENTIAL MUTUAL FUND | F33: ='Raw CF'!E33 -> 15.288944 | G33: ='Raw CF'!F33 -> 0.0411 | H33: ='Raw CF'!G33 -> 19837.405
B34: ='Raw CF'!D34 -> National Pension System Trust | F34: ='Raw CF'!E34 -> 10.006455 | G34: ='Raw CF'!F34 -> 0.0269 | H34: ='Raw CF'!G34 -> 12983.375
B35: ='Raw CF'!D35 -> SUDHA GOPALAKRISHNAN | F35: ='Raw CF'!E35 -> 9.5357 | G35: ='Raw CF'!F35 -> 0.0257 | H35: ='Raw CF'!G35 -> 12372.571
B36: ='Raw CF'!D36 -> HDFC MUTUAL FUND | F36: ='Raw CF'!E36 -> 6.8989087 | G36: ='Raw CF'!F36 -> 0.0186 | H36: ='Raw CF'!G36 -> 8951.334
B37: ='Raw CF'!D37 -> UTI MUTUAL FUND | F37: ='Raw CF'!E37 -> 6.7112909 | G37: ='Raw CF'!F37 -> 0.0181 | H37: ='Raw CF'!G37 -> 8707.8999
B38: ='Raw CF'!D38 -> NIPPON LIFE INDIA TRUSTEE | F38: ='Raw CF'!E38 -> 6.5708729 | G38: ='Raw CF'!F38 -> 0.0177 | H38: ='Raw CF'!G38 -> 8525.7076
B39: ='Raw CF'!D39 -> ROHAN MURTY | F39: ='Raw CF'!E39 -> 6.0812892 | G39: ='Raw CF'!F39 -> 0.0164 | H39: ='Raw CF'!G39 -> 7890.4727
B40: ='Raw CF'!D40 -> VANGUARD TOTAL INTERNATIONAL STOCK INDEX FUND | F40: ='Raw CF'!E40 -> 5.139239 | G40: ='Raw CF'!F40 -> 0.0138 | H40: ='Raw CF'!G40 -> 6668.1626
B42: Managerial Remuneration | F42: Designations | G42: Since | H42: Salary (Crs.) | J42: Capital Structure
B44: Salil Parikh | F44: CEO & MD | G44: 2018 | H44: 80.62 | J44: Share Price as on 03/04/2026 | O44: 1300.8
B45: Karmesh Gul Vashwani | E45: Segment Head - CPG, Logistic & Retail | G45: 2003 | H45: 21.64 | J45: No. of Share | O45: ='Data Sheet'!B6 -> 405.53911
B46: Inderpreet Sawhaney | F46: CLO | G46: 2017 | H46: 20.09 | J46: Market Capitalisation | O46: =O44*O45 -> 527525.27
B47: Martha king | F47: CCO | G47: 2020 | H47: 16.08 | J47: less: Cash & Cash equivalents | O47: =-'Data Sheet'!K69 -> -24455
B48: Jasmeet singh | E48: Segment Head - Manufacturing | G48: 2011 | H48: 14.88 | J48: Add: Total Debt | O48: ='Data Sheet'!K59 -> 8227
J49: Add: Minority Interest | O49: 385
J50: Enterprise Value | O50: =SUM(O46:O49) -> 511682.27
...

Sheet  Financials>

Sheet Historical FS
B4: ='Data Sheet'!$B$1 -> INFOSYS LTD
B5: ( NSE: INFY | BSE: 500209)
B6: 1250
B7: 52 Week (High 1728 & Low 1215)
B10: ="Historical Financial Statements" -> Historical Financial Statements
B11: Particulars | C11: ='Data Sheet'!B16 -> 42460 | D11: ='Data Sheet'!C16 -> 42825 | E11: ='Data Sheet'!D16 -> 43190 | F11: ='Data Sheet'!E16 -> 43555 | G11: ='Data Sheet'!F16 -> 43921 | H11: ='Data Sheet'!G16 -> 44286 | I11: ='Data Sheet'!H16 -> 44651 | J11: ='Data Sheet'!I16 -> 45016 | ... L11: ='Data Sheet'!K16 -> 45747 | M11: LTM
A13: # | B13: Income Statement
B14: Sales | C14: =IFERROR('Data Sheet'!B17,"-") -> 62441 | D14: =IFERROR('Data Sheet'!C17,"-") -> 68484 | E14: =IFERROR('Data Sheet'!D17,"-") -> 70522 | F14: =IFERROR('Data Sheet'!E17,"-") -> 82675 | G14: =IFERROR('Data Sheet'!F17,"-") -> 90791 | H14: =IFERROR('Data Sheet'!G17,"-") -> 100472 | I14: =IFERROR('Data Sheet'!H17,"-") -> 121641 | J14: =IFERROR('Data Sheet'!I17,"-") -> 146767 | ... L14: =IFERROR('Data Sheet'!K17,"-") -> 162990 | M14: =IFERROR(SUM('Data Sheet'!H42:K42),"-") -> 173173
B15: Sales Growth % | C15: - | D15: =IFERROR(D14/C14-1,"-") -> 0.09677936 | E15: =IFERROR(E14/D14-1,"-") -> 0.029758776 | F15: =IFERROR(F14/E14-1,"-") -> 0.1723292 | G15: =IFERROR(G14/F14-1,"-") -> 0.098167523 | H15: =IFERROR(H14/G14-1,"-") -> 0.10662951 | I15: =IFERROR(I14/H14-1,"-") -> 0.21069552 | J15: =IFERROR(J14/I14-1,"-") -> 0.20655864 | K15: =IFERROR(K14/J14-1,"-") -> 0.047033734 | ... M15: =IFERROR(M14/L14-1,"-") -> 0.062476226
B17: COGS | C17: =IFERROR(SUM('Data Sheet'!B20:B22),"-") -> 40492 | D17: =IFERROR(SUM('Data Sheet'!C20:C22),"-") -> 44609 | E17: =IFERROR(SUM('Data Sheet'!D20:D22),"-") -> 46395 | F17: =IFERROR(SUM('Data Sheet'!E20:E22),"-") -> 55446 | G17: =IFERROR(SUM('Data Sheet'!F20:F22),"-") -> 62210 | H17: =IFERROR(SUM('Data Sheet'!G20:G22),"-") -> 68490 | I17: =IFERROR(SUM('Data Sheet'!H20:H22),"-") -> 84819 | J17: =IFERROR(SUM('Data Sheet'!I20:I22),"-") -> 104880 | ... L17: =IFERROR(SUM('Data Sheet'!K20:K22),"-") -> 116585 | M17: =IFERROR(SUM('Data Sheet'!H43:K43),"-") -> 132187
B18: COGS % sale | C18: =IFERROR(C17/C14,"-") -> 0.64848417 | D18: =IFERROR(D17/D14,"-") -> 0.65137842 | E18: =IFERROR(E17/E14,"-") -> 0.65787981 | F18: =IFERROR(F17/F14,"-") -> 0.67065014 | G18: =IFERROR(G17/G14,"-") -> 0.68520007 | H18: =IFERROR(H17/H14,"-") -> 0.68168246 | I18: =IFERROR(I17/I14,"-") -> 0.69728957 | J18: =IFERROR(J17/J14,"-") -> 0.71460206 | ... M18: =IFERROR(M17/M14,"-") -> 0.76332338
B20: Gross Profit | C20: =IFERROR(C14-C17,"-") -> 21949 | D20: =IFERROR(D14-D17,"-") -> 23875 | E20: =IFERROR(E14-E17,"-") -> 24127 | F20: =IFERROR(F14-F17,"-") -> 27229 | G20: =IFERROR(G14-G17,"-") -> 28581 | H20: =IFERROR(H14-H17,"-") -> 31982 | I20: =IFERROR(I14-I17,"-") -> 36822 | J20: =IFERROR(J14-J17,"-") -> 41887 | ... M20: =IFERROR(M14-M17,"-") -> 40986
B21: Gross Margin | C21: =IFERROR(C20/C14,"-") -> 0.35151583 | D21: =IFERROR(D20/D14,"-") -> 0.34862158 | E21: =IFERROR(E20/E14,"-") -> 0.34212019 | F21: =IFERROR(F20/F14,"-") -> 0.32934986 | G21: =IFERROR(G20/G14,"-") -> 0.31479993 | H21: =IFERROR(H20/H14,"-") -> 0.31831754 | I21: =IFERROR(I20/I14,"-") -> 0.30271043 | J21: =IFERROR(J20/J14,"-") -> 0.28539794 | ... M21: =IFERROR(M20/M14,"-") -> 0.23667662
B23: Selling, General & Admin. Exp. | C23: =IFERROR(SUM('Data Sheet'!B23:B24),"-") -> 4870 | D23: =IFERROR(SUM('Data Sheet'!C23:C24),"-") -> 5271 | E23: =IFERROR(SUM('Data Sheet'!D23:D24),"-") -> 5305 | F23: =IFERROR(SUM('Data Sheet'!E23:E24),"-") -> 7059 | G23: =IFERROR(SUM('Data Sheet'!F23:F24),"-") -> 6314 | H23: =IFERROR(SUM('Data Sheet'!G23:G24),"-") -> 4093 | I23: =IFERROR(SUM('Data Sheet'!H23:H24),"-") -> 5331 | J23: =IFERROR(SUM('Data Sheet'!I23:I24),"-") -> 6757 | ... L23: =IFERROR(SUM('Data Sheet'!K23:K24),"-") -> 7169
B24: SG&A expense % sale | C24: =IFERROR(C23/C14,"-") -> 0.077993626 | D24: =IFERROR(D23/D14,"-") -> 0.076966883 | E24: =IFERROR(E23/E14,"-") -> 0.075224753 | F24: =IFERROR(F23/F14,"-") -> 0.085382522 | G24: =IFERROR(G23/G14,"-") -> 0.069544338 | H24: =IFERROR(H23/H14,"-") -> 0.040737718 | I24: =IFERROR(I23/I14,"-") -> 0.043825684 | J24: =IFERROR(J23/J14,"-") -> 0.04603896 | ... M24: =IFERROR(M23/M14,"-") -> 0
B26: EBITDA | C26: =IFERROR(C20-C23,"-") -> 17079 | D26: =IFERROR(D20-D23,"-") -> 18604 | E26: =IFERROR(E20-E23,"-") -> 18822 | F26: =IFERROR(F20-F23,"-") -> 20170 | G26: =IFERROR(G20-G23,"-") -> 22267 | H26: =IFERROR(H20-H23,"-") -> 27889 | I26: =IFERROR(I20-I23,"-") -> 31491 | J26: =IFERROR(J20-J23,"-") -> 35130 | ... M26: =IFERROR(M20-M23,"-") -> 40986
B27: EBITDA Margin | C27: =IFERROR(C26/C14,"-") -> 0.2735222 | D27: =IFERROR(D26/D14,"-") -> 0.27165469 | E27: =IFERROR(E26/E14,"-") -> 0.26689544 | F27: =IFERROR(F26/F14,"-") -> 0.24396734 | G27: =IFERROR(G26/G14,"-") -> 0.24525559 | H27: =IFERROR(H26/H14,"-") -> 0.27757982 | I27: =IFERROR(I26/I14,"-") -> 0.25888475 | J27: =IFERROR(J26/J14,"-") -> 0.23935898 | ... M27: =IFERROR(M26/M14,"-") -> 0.23667662
B29: Depreciation | C29: =IFERROR('Data Sheet'!B26,"-") -> 1459 | D29: =IFERROR('Data Sheet'!C26,"-") -> 1703 | E29: =IFERROR('Data Sheet'!D26,"-") -> 1863 | F29: =IFERROR('Data Sheet'!E26,"-") -> 2011 | G29: =IFERROR('Data Sheet'!F26,"-") -> 2893 | H29: =IFERROR('Data Sheet'!G26,"-") -> 3267 | I29: =IFERROR('Data Sheet'!H26,"-") -> 3476 | J29: =IFERROR('Data Sheet'!I26,"-") -> 4225 | ... L29: =IFERROR('Data Sheet'!K26,"-") -> 4812 | M29: =IFERROR(SUM('Data Sheet'!H45:K45),"-") -> 4776
B30: Dep. % Sale | C30: =IFERROR(C29/C14,"-") -> 0.023366058 | D30: =IFERROR(D29/D14,"-") -> 0.024867122 | E30: =IFERROR(E29/E14,"-") -> 0.026417288 | F30: =IFERROR(F29/F14,"-") -> 0.024324161 | G30: =IFERROR(G29/G14,"-") -> 0.031864392 | H30: =IFERROR(H29/H14,"-") -> 0.032516522 | I30: =IFERROR(I29/I14,"-") -> 0.028575891 | J30: =IFERROR(J29/J14,"-") -> 0.028787125 | ... M30: =IFERROR(M29/M14,"-") -> 0.027579357
B32: EBIT | C32: =IFERROR(C26-C29,"-") -> 15620 | D32: =IFERROR(D26-D29,"-") -> 16901 | E32: =IFERROR(E26-E29,"-") -> 16959 | F32: =IFERROR(F26-F29,"-") -> 18159 | G32: =IFERROR(G26-G29,"-") -> 19374 | H32: =IFERROR(H26-H29,"-") -> 24622 | I32: =IFERROR(I26-I29,"-") -> 28015 | J32: =IFERROR(J26-J29,"-") -> 30905 | ... M32: =IFERROR(M26-M29,"-") -> 36210
B33: EBIT Margin | C33: =IFERROR(C32/C14,"-") -> 0.25015615 | D33: =IFERROR(D32/D14,"-") -> 0.24678757 | E33: =IFERROR(E32/E14,"-") -> 0.24047815 | F33: =IFERROR(F32/F14,"-") -> 0.21964318 | G33: =IFERROR(G32/G14,"-") -> 0.2133912 | H33: =IFERROR(H32/H14,"-") -> 0.2450633 | I33: =IFERROR(I32/I14,"-") -> 0.23030886 | J33: =IFERROR(J32/J14,"-") -> 0.21057186 | ... M33: =IFERROR(M32/M14,"-") -> 0.20909726
B35: Other Income | C35: =IFERROR('Data Sheet'!B25,"-") -> 3120 | D35: =IFERROR('Data Sheet'!C25,"-") -> 3050 | E35: =IFERROR('Data Sheet'!D25,"-") -> 3311 | F35: =IFERROR('Data Sheet'!E25,"-") -> 2882 | G35: =IFERROR('Data Sheet'!F25,"-") -> 2803 | H35: =IFERROR('Data Sheet'!G25,"-") -> 2201 | I35: =IFERROR('Data Sheet'!H25,"-") -> 2295 | J35: =IFERROR('Data Sheet'!I25,"-") -> 2701 | ... L35: =IFERROR('Data Sheet'!K25,"-") -> 3600 | M35: =IFERROR(SUM('Data Sheet'!H44:K44),"-") -> 3064
B36: OI % Sale | C36: =IFERROR(C35/C14,"-") -> 0.049967169 | D36: =IFERROR(D35/D14,"-") -> 0.04453595 | E36: =IFERROR(E35/E14,"-") -> 0.046949888 | F36: =IFERROR(F35/F14,"-") -> 0.034859389 | G36: =IFERROR(G35/G14,"-") -> 0.030873104 | H36: =IFERROR(H35/H14,"-") -> 0.021906601 | I36: =IFERROR(I35/I14,"-") -> 0.018866994 | J36: =IFERROR(J35/J14,"-") -> 0.01840332 | ... M36: =IFERROR(M35/M14,"-") -> 0.017693289
B38: Interest | C38: =IFERROR('Data Sheet'!B27,"-") -> 0 | D38: =IFERROR('Data Sheet'!C27,"-") -> 0 | E38: =IFERROR('Data Sheet'!D27,"-") -> 0 | F38: =IFERROR('Data Sheet'!E27,"-") -> 0 | G38: =IFERROR('Data Sheet'!F27,"-") -> 170 | H38: =IFERROR('Data Sheet'!G27,"-") -> 195 | I38: =IFERROR('Data Sheet'!H27,"-") -> 200 | J38: =IFERROR('Data Sheet'!I27,"-") -> 284 | ... L38: =IFERROR('Data Sheet'!K27,"-") -> 416 | M38: =IFERROR(SUM('Data Sheet'!H46:K46),"-") -> 413
B39: Int. % Sale | C39: =IFERROR(C38/C14,"-") -> 0 | D39: =IFERROR(D38/D14,"-") -> 0 | E39: =IFERROR(E38/E14,"-") -> 0 | F39: =IFERROR(F38/F14,"-") -> 0 | G39: =IFERROR(G38/G14,"-") -> 0.0018724323 | H39: =IFERROR(H38/H14,"-") -> 0.0019408392 | I39: =IFERROR(I38/I14,"-") -> 0.0016441825 | J39: =IFERROR(J38/J14,"-") -> 0.0019350399 | ... M39: =IFERROR(M38/M14,"-") -> 0.0023848983
B41: EBT / Profit before tax | C41: =IFERROR(C32+C35-C38,"-") -> 18740 | D41: =IFERROR(D32+D35-D38,"-") -> 19951 | E41: =IFERROR(E32+E35-E38,"-") -> 20270 | F41: =IFERROR(F32+F35-F38,"-") -> 21041 | G41: =IFERROR(G32+G35-G38,"-") -> 22007 | H41: =IFERROR(H32+H35-H38,"-") -> 26628 | I41: =IFERROR(I32+I35-I38,"-") -> 30110 | J41: =IFERROR(J32+J35-J38,"-") -> 33322 | ... M41: =IFERROR(M32+M35-M38,"-") -> 38861
B42: EBT % Margin | C42: =IFERROR(C41/C14,"-") -> 0.30012332 | D42: =IFERROR(D41/D14,"-") -> 0.29132352 | E42: =IFERROR(E41/E14,"-") -> 0.28742804 | F42: =IFERROR(F41/F14,"-") -> 0.25450257 | G42: =IFERROR(G41/G14,"-") -> 0.24239187 | H42: =IFERROR(H41/H14,"-") -> 0.26502906 | I42: =IFERROR(I41/I14,"-") -> 0.24753167 | J42: =IFERROR(J41/J14,"-") -> 0.22704014 | ... M42: =IFERROR(M41/M14,"-") -> 0.22440565
B44: Tax | C44: =IFERROR('Data Sheet'!B29,"-") -> 5251 | D44: =IFERROR('Data Sheet'!C29,"-") -> 5598 | E44: =IFERROR('Data Sheet'!D29,"-") -> 4241 | F44: =IFERROR('Data Sheet'!E29,"-") -> 5631 | G44: =IFERROR('Data Sheet'!F29,"-") -> 5368 | H44: =IFERROR('Data Sheet'!G29,"-") -> 7205 | I44: =IFERROR('Data Sheet'!H29,"-") -> 7964 | J44: =IFERROR('Data Sheet'!I29,"-") -> 9214 | ... L44: =IFERROR('Data Sheet'!K29,"-") -> 10858 | M44: =IFERROR(SUM('Data Sheet'!H48:K48),"-") -> 10858
B45: Effective tax rate | C45: =IFERROR(C44/C41,"-") -> 0.28020277 | D45: =IFERROR(D44/D41,"-") -> 0.28058744 | E45: =IFERROR(E44/E41,"-") -> 0.20922546 | F45: =IFERROR(F44/F41,"-") -> 0.26762036 | G45: =IFERROR(G44/G41,"-") -> 0.24392239 | H45: =IFERROR(H44/H41,"-") -> 0.27057984 | I45: =IFERROR(I44/I41,"-") -> 0.26449684 | J45: =IFERROR(J44/J41,"-") -> 0.27651401 | ... M45: =IFERROR(M44/M41,"-") -> 0.27940609
B47: Net Profit | C47: =IFERROR(C41-C44,"-") -> 13489 | D47: =IFERROR(D41-D44,"-") -> 14353 | E47: =IFERROR(E41-E44,"-") -> 16029 | F47: =IFERROR(F41-F44,"-") -> 15410 | G47: =IFERROR(G41-G44,"-") -> 16639 | H47: =IFERROR(H41-H44,"-") -> 19423 | I47: =IFERROR(I41-I44,"-") -> 22146 | J47: =IFERROR(J41-J44,"-") -> 24108 | ... M47: =IFERROR(M41-M44,"-") -> 28003
B48: Net Margin | C48: =IFERROR(C47/C14,"-") -> 0.21602793 | D48: =IFERROR(D47/D14,"-") -> 0.2095818 | E48: =IFERROR(E47/E14,"-") -> 0.22729077 | F48: =IFERROR(F47/F14,"-") -> 0.1863925 | G48: =IFERROR(G47/G14,"-") -> 0.18326706 | H48: =IFERROR(H47/H14,"-") -> 0.19331754 | I48: =IFERROR(I47/I14,"-") -> 0.18206033 | J48: =IFERROR(J47/J14,"-") -> 0.16426036 | ... M48: =IFERROR(M47/M14,"-") -> 0.16170535
B50: No. of Equity Share (CR.) | C50: =IFERROR('Data Sheet'!B93,"-") -> 459.39 | D50: =IFERROR('Data Sheet'!C93,"-") -> 459.39 | E50: =IFERROR('Data Sheet'!D93,"-") -> 436.82 | F50: =IFERROR('Data Sheet'!E93,"-") -> 436.89 | G50: =IFERROR('Data Sheet'!F93,"-") -> 425.9 | H50: =IFERROR('Data Sheet'!G93,"-") -> 426.07 | I50: =IFERROR('Data Sheet'!H93,"-") -> 420.67 | J50: =IFERROR('Data Sheet'!I93,"-") -> 414.86 | ... L50: =IFERROR('Data Sheet'!K93,"-") -> 415.33
B52: Earning per share | C52: =IFERROR(C47/C50,"-") -> 29.362851 | D52: =IFERROR(D47/D50,"-") -> 31.243606 | E52: =IFERROR(E47/E50,"-") -> 36.694748 | F52: =IFERROR(F47/F50,"-") -> 35.272036 | G52: =IFERROR(G47/G50,"-") -> 39.067856 | H52: =IFERROR(H47/H50,"-") -> 45.586406 | I52: =IFERROR(I47/I50,"-") -> 52.644591 | J52: =IFERROR(J47/J50,"-") -> 58.11117 | ... L52: =IFERROR(L47/L50,"-") -> 64.406616
B53: EPS growth % | C53: - | D53: =IFERROR(D52/C52,"-") -> 1.0640522 | E53: =IFERROR(E52/D52,"-") -> 1.1744723 | F53: =IFERROR(F52/E52,"-") -> 0.96122846 | G53: =IFERROR(G52/F52,"-") -> 1.1076156 | H53: =IFERROR(H52/G52,"-") -> 1.166852 | I53: =IFERROR(I52/H52,"-") -> 1.1548309 | J53: =IFERROR(J52/I52,"-") -> 1.1038393 | K53: =IFERROR(K52/J52,"-") -> 1.0881639 | L53: =IFERROR(L52/K52,"-") -> 1.0185364
B55: Dividend per share | C55: =IFERROR('Data Sheet'!B31/C50,"-") -> 12.077755 | D55: =IFERROR('Data Sheet'!C31/D50,"-") -> 12.824833 | E55: =IFERROR('Data Sheet'!D31/E50,"-") -> 21.669337 | F55: =IFERROR('Data Sheet'!E31/F50,"-") -> 21.109433 | G55: =IFERROR('Data Sheet'!F31/G50,"-") -> 17.438366 | H55: =IFERROR('Data Sheet'!G31/H50,"-") -> 26.91952 | I55: =IFERROR('Data Sheet'!H31/I50,"-") -> 30.92115 | J55: =IFERROR('Data Sheet'!I31/J50,"-") -> 33.913127 | ... L55: =IFERROR('Data Sheet'!K31/L50,"-") -> 42.924422
B56: Dividend Payout ratio | C56: =IFERROR(C55/C52,"-") -> 0.41132775 | D56: =IFERROR(D55/D52,"-") -> 0.41047865 | E56: =IFERROR(E55/E52,"-") -> 0.59052966 | F56: =IFERROR(F55/F52,"-") -> 0.59847502 | G56: =IFERROR(G55/G52,"-") -> 0.44636096 | H56: =IFERROR(H55/H52,"-") -> 0.5905164 | I56: =IFERROR(I55/I52,"-") -> 0.58735663 | J56: =IFERROR(J55/J52,"-") -> 0.58359051 | ... L56: =IFERROR(L55/L52,"-") -> 0.66645981
B58: Retained Earnings | C58: =IFERROR(IF(C52>C55,1-C56,0),"-") -> 0.58867225 | D58: =IFERROR(IF(D52>D55,1-D56,0),"-") -> 0.58952135 | E58: =IFERROR(IF(E52>E55,1-E56,0),"-") -> 0.40947034 | F58: =IFERROR(IF(F52>F55,1-F56,0),"-") -> 0.40152498 | G58: =IFERROR(IF(G52>G55,1-G56,0),"-") -> 0.55363904 | H58: =IFERROR(IF(H52>H55,1-H56,0),"-") -> 0.4094836 | I58: =IFERROR(IF(I52>I55,1-I56,0),"-") -> 0.41264337 | J58: =IFERROR(IF(J52>J55,1-J56,0),"-") -> 0.41640949 | ... L58: =IFERROR(IF(L52>L55,1-L56,0),"-") -> 0.33354019
A63: # | B63: Balance Sheet
B64: Equity Share Capital | C64: =IFERROR('Data Sheet'!B57,"-") -> 1144 | D64: =IFERROR('Data Sheet'!C57,"-") -> 1144 | E64: =IFERROR('Data Sheet'!D57,"-") -> 1088 | F64: =IFERROR('Data Sheet'!E57,"-") -> 2170 | G64: =IFERROR('Data Sheet'!F57,"-") -> 2122 | H64: =IFERROR('Data Sheet'!G57,"-") -> 2124 | I64: =IFERROR('Data Sheet'!H57,"-") -> 2098 | J64: =IFERROR('Data Sheet'!I57,"-") -> 2069 | ... L64: =IFERROR('Data Sheet'!K57,"-") -> 2073
B65: Reserves | C65: =IFERROR('Data Sheet'!B58,"-") -> 60600 | D65: =IFERROR('Data Sheet'!C58,"-") -> 67838 | E65: =IFERROR('Data Sheet'!D58,"-") -> 63835 | F65: =IFERROR('Data Sheet'!E58,"-") -> 62778 | G65: =IFERROR('Data Sheet'!F58,"-") -> 63328 | H65: =IFERROR('Data Sheet'!G58,"-") -> 74227 | I65: =IFERROR('Data Sheet'!H58,"-") -> 73252 | J65: =IFERROR('Data Sheet'!I58,"-") -> 73338 | ... L65: =IFERROR('Data Sheet'!K58,"-") -> 93745
...

Sheet Ratio Analysis
B4: ='Data Sheet'!$B$1 -> INFOSYS LTD
B5: ( NSE: INFY | BSE: 500209)
B6: 1250
B7: 52 Week (High 1728 & Low 1215)
B10: ="Ratio Analysis" -> Ratio Analysis
B11: Particulars | C11: ='Data Sheet'!B16 -> 42460 | D11: ='Data Sheet'!C16 -> 42825 | E11: ='Data Sheet'!D16 -> 43190 | F11: ='Data Sheet'!E16 -> 43555 | G11: ='Data Sheet'!F16 -> 43921 | H11: ='Data Sheet'!G16 -> 44286 | I11: ='Data Sheet'!H16 -> 44651 | J11: ='Data Sheet'!I16 -> 45016 | ... L11: ='Data Sheet'!K16 -> 45747 | M11: Trend | N11: Mean | O11: Median
B13: Sales Growth | C13: - | D13: ='Historical FS'!D15 -> 0.09677936 | E13: ='Historical FS'!E15 -> 0.029758776 | F13: ='Historical FS'!F15 -> 0.1723292 | G13: ='Historical FS'!G15 -> 0.098167523 | H13: ='Historical FS'!H15 -> 0.10662951 | I13: ='Historical FS'!I15 -> 0.21069552 | J13: ='Historical FS'!J15 -> 0.20655864 | K13: ='Historical FS'!K15 -> 0.047033734 | L13: ='Historical FS'!L15 -> 0.060649444 | N13: =IFERROR(AVERAGE(D13:L13),"-") -> 0.11428908 | O13: =IFERROR(MEDIAN(C13:L13),"-") -> 0.098167523
B14: EBITDA Growth | C14: - | D14: =IFERROR('Historical FS'!D26/'Historical FS'!C26-1,"-") -> 0.089290942 | E14: =IFERROR('Historical FS'!E26/'Historical FS'!D26-1,"-") -> 0.01171791 | F14: =IFERROR('Historical FS'!F26/'Historical FS'!E26-1,"-") -> 0.071618319 | G14: =IFERROR('Historical FS'!G26/'Historical FS'!F26-1,"-") -> 0.10396629 | H14: =IFERROR('Historical FS'!H26/'Historical FS'!G26-1,"-") -> 0.25248125 | I14: =IFERROR('Historical FS'!I26/'Historical FS'!H26-1,"-") -> 0.12915486 | J14: =IFERROR('Historical FS'!J26/'Historical FS'!I26-1,"-") -> 0.11555683 | K14: =IFERROR('Historical FS'!K26/'Historical FS'!J26-1,"-") -> 0.03686308 | L14: =IFERROR('Historical FS'!L26/'Historical FS'!K26-1,"-") -> 0.077172272 | N14: =IFERROR(AVERAGE(D14:L14),"-") -> 0.098646861 | O14: =IFERROR(MEDIAN(C14:L14),"-") -> 0.089290942
B15: EBIT Growth | C15: - | D15: =IFERROR('Historical FS'!D32/'Historical FS'!C32-1,"-") -> 0.082010243 | E15: =IFERROR('Historical FS'!E32/'Historical FS'!D32-1,"-") -> 0.0034317496 | F15: =IFERROR('Historical FS'!F32/'Historical FS'!E32-1,"-") -> 0.070758889 | G15: =IFERROR('Historical FS'!G32/'Historical FS'!F32-1,"-") -> 0.066908971 | H15: =IFERROR('Historical FS'!H32/'Historical FS'!G32-1,"-") -> 0.2708785 | I15: =IFERROR('Historical FS'!I32/'Historical FS'!H32-1,"-") -> 0.13780359 | J15: =IFERROR('Historical FS'!J32/'Historical FS'!I32-1,"-") -> 0.10315902 | K15: =IFERROR('Historical FS'!K32/'Historical FS'!J32-1,"-") -> 0.027244782 | L15: =IFERROR('Historical FS'!L32/'Historical FS'!K32-1,"-") -> 0.084322928 | N15: =IFERROR(AVERAGE(D15:L15),"-") -> 0.09405763 | O15: =IFERROR(MEDIAN(C15:L15),"-") -> 0.082010243
B16: Net Profit Growth | C16: - | D16: =IFERROR('Historical FS'!D47/'Historical FS'!C47-1,"-") -> 0.064052191 | E16: =IFERROR('Historical FS'!E47/'Historical FS'!D47-1,"-") -> 0.11677001 | F16: =IFERROR('Historical FS'!F47/'Historical FS'!E47-1,"-") -> -0.038617506 | G16: =IFERROR('Historical FS'!G47/'Historical FS'!F47-1,"-") -> 0.079753407 | H16: =IFERROR('Historical FS'!H47/'Historical FS'!G47-1,"-") -> 0.16731775 | I16: =IFERROR('Historical FS'!I47/'Historical FS'!H47-1,"-") -> 0.14019461 | J16: =IFERROR('Historical FS'!J47/'Historical FS'!I47-1,"-") -> 0.088593877 | K16: =IFERROR('Historical FS'!K47/'Historical FS'!J47-1,"-") -> 0.088767214 | L16: =IFERROR('Historical FS'!L47/'Historical FS'!K47-1,"-") -> 0.019125267 | N16: =IFERROR(AVERAGE(D16:L16),"-") -> 0.080661869 | O16: =IFERROR(MEDIAN(C16:L16),"-") -> 0.088593877
B17: Dividend Growth | C17: - | D17: =IFERROR('Historical FS'!D55/'Historical FS'!C55-1,"-") -> 0.06185567 | E17: =IFERROR('Historical FS'!E55/'Historical FS'!D55-1,"-") -> 0.68963897 | F17: =IFERROR('Historical FS'!F55/'Historical FS'!E55-1,"-") -> -0.02583858 | G17: =IFERROR('Historical FS'!G55/'Historical FS'!F55-1,"-") -> -0.17390646 | H17: =IFERROR('Historical FS'!H55/'Historical FS'!G55-1,"-") -> 0.54369512 | I17: =IFERROR('Historical FS'!I55/'Historical FS'!H55-1,"-") -> 0.14865158 | J17: =IFERROR('Historical FS'!J55/'Historical FS'!I55-1,"-") -> 0.096761529 | K17: =IFERROR('Historical FS'!K55/'Historical FS'!J55-1,"-") -> 0.35349861 | L17: =IFERROR('Historical FS'!L55/'Historical FS'!K55-1,"-") -> -0.064855345 | N17: =IFERROR(AVERAGE(D17:L17),"-") -> 0.18105568 | O17: =IFERROR(MEDIAN(C17:L17),"-") -> 0.096761529
B19: Gross Margin | C19: ='Historical FS'!C21 -> 0.35151583 | D19: ='Historical FS'!D21 -> 0.34862158 | E19: ='Historical FS'!E21 -> 0.34212019 | F19: ='Historical FS'!F21 -> 0.32934986 | G19: ='Historical FS'!G21 -> 0.31479993 | H19: ='Historical FS'!H21 -> 0.31831754 | I19: ='Historical FS'!I21 -> 0.30271043 | J19: ='Historical FS'!J21 -> 0.28539794 | ... L19: ='Historical FS'!L21 -> 0.28471072 | N19: =IFERROR(AVERAGE(C19:L19),"-") -> 0.31615292 | O19: =IFERROR(MEDIAN(C19:L19),"-") -> 0.31655873
B20: EBITDA Margin | C20: ='Historical FS'!C27 -> 0.2735222 | D20: ='Historical FS'!D27 -> 0.27165469 | E20: ='Historical FS'!E27 -> 0.26689544 | F20: ='Historical FS'!F27 -> 0.24396734 | G20: ='Historical FS'!G27 -> 0.24525559 | H20: ='Historical FS'!H27 -> 0.27757982 | I20: ='Historical FS'!I27 -> 0.25888475 | J20: ='Historical FS'!J27 -> 0.23935898 | ... L20: ='Historical FS'!L27 -> 0.24072642 | N20: =IFERROR(AVERAGE(C20:L20),"-") -> 0.25548792 | O20: =IFERROR(MEDIAN(C20:L20),"-") -> 0.25207017
B21: EBIT Margin | C21: ='Historical FS'!C33 -> 0.25015615 | D21: ='Historical FS'!D33 -> 0.24678757 | E21: ='Historical FS'!E33 -> 0.24047815 | F21: ='Historical FS'!F33 -> 0.21964318 | G21: ='Historical FS'!G33 -> 0.2133912 | H21: ='Historical FS'!H33 -> 0.2450633 | I21: ='Historical FS'!I33 -> 0.23030886 | J21: ='Historical FS'!J33 -> 0.21057186 | ... L21: ='Historical FS'!L33 -> 0.21120314 | N21: =IFERROR(AVERAGE(C21:L21),"-") -> 0.22741955 | O21: =IFERROR(MEDIAN(C21:L21),"-") -> 0.22497602
B22: EBT Margin | C22: ='Historical FS'!C42 -> 0.30012332 | D22: ='Historical FS'!D42 -> 0.29132352 | E22: ='Historical FS'!E42 -> 0.28742804 | F22: ='Historical FS'!F42 -> 0.25450257 | G22: ='Historical FS'!G42 -> 0.24239187 | H22: ='Historical FS'!H42 -> 0.26502906 | I22: ='Historical FS'!I42 -> 0.24753167 | J22: ='Historical FS'!J42 -> 0.22704014 | ... L22: ='Historical FS'!L42 -> 0.23073808 | N22: =IFERROR(AVERAGE(C22:L22),"-") -> 0.25802984 | O22: =IFERROR(MEDIAN(C22:L22),"-") -> 0.25101712
B23: Net Profit Margin | C23: ='Historical FS'!C48 -> 0.21602793 | D23: ='Historical FS'!D48 -> 0.2095818 | E23: ='Historical FS'!E48 -> 0.22729077 | F23: ='Historical FS'!F48 -> 0.1863925 | G23: ='Historical FS'!G48 -> 0.18326706 | H23: ='Historical FS'!H48 -> 0.19331754 | I23: ='Historical FS'!I48 -> 0.18206033 | J23: ='Historical FS'!J48 -> 0.16426036 | ... L23: ='Historical FS'!L48 -> 0.1641205 | N23: =IFERROR(AVERAGE(C23:L23),"-") -> 0.18971264 | O23: =IFERROR(MEDIAN(C23:L23),"-") -> 0.18482978
B25: Sales Expense % Sales | C25: ='Historical FS'!C24 -> 0.077993626 | D25: ='Historical FS'!D24 -> 0.076966883 | E25: ='Historical FS'!E24 -> 0.075224753 | F25: ='Historical FS'!F24 -> 0.085382522 | G25: ='Historical FS'!G24 -> 0.069544338 | H25: ='Historical FS'!H24 -> 0.040737718 | I25: ='Historical FS'!I24 -> 0.043825684 | J25: ='Historical FS'!J24 -> 0.04603896 | ... L25: ='Historical FS'!L24 -> 0.043984294 | N25: =IFERROR(AVERAGE(C25:L25),"-") -> 0.060665004 | O25: =IFERROR(MEDIAN(C25:L25),"-") -> 0.058247799
B26: Depreciation % Sales | C26: ='Historical FS'!C30 -> 0.023366058 | D26: ='Historical FS'!D30 -> 0.024867122 | E26: ='Historical FS'!E30 -> 0.026417288 | F26: ='Historical FS'!F30 -> 0.024324161 | G26: ='Historical FS'!G30 -> 0.031864392 | H26: ='Historical FS'!H30 -> 0.032516522 | I26: ='Historical FS'!I30 -> 0.028575891 | J26: ='Historical FS'!J30 -> 0.028787125 | ... L26: ='Historical FS'!L30 -> 0.029523284 | N26: =IFERROR(AVERAGE(C26:L26),"-") -> 0.02806837 | O26: =IFERROR(MEDIAN(C26:L26),"-") -> 0.028681508
B27: Operating Income % sales | C27: ='Historical FS'!C27 -> 0.2735222 | D27: ='Historical FS'!D27 -> 0.27165469 | E27: ='Historical FS'!E27 -> 0.26689544 | F27: ='Historical FS'!F27 -> 0.24396734 | G27: ='Historical FS'!G27 -> 0.24525559 | H27: ='Historical FS'!H27 -> 0.27757982 | I27: ='Historical FS'!I27 -> 0.25888475 | J27: ='Historical FS'!J27 -> 0.23935898 | ... L27: ='Historical FS'!L27 -> 0.24072642 | N27: =IFERROR(AVERAGE(C27:L27),"-") -> 0.25548792 | O27: =IFERROR(MEDIAN(C27:L27),"-") -> 0.25207017
B29: Return on Capital Employed | C29: =IFERROR('Historical FS'!C26/SUM('Historical FS'!C64:C66),"-") -> 0.27660987 | D29: =IFERROR('Historical FS'!D26/SUM('Historical FS'!D64:D66),"-") -> 0.26969354 | E29: =IFERROR('Historical FS'!E26/SUM('Historical FS'!E64:E66),"-") -> 0.28991267 | F29: =IFERROR('Historical FS'!F26/SUM('Historical FS'!F64:F66),"-") -> 0.31055614 | G29: =IFERROR('Historical FS'!G26/SUM('Historical FS'!G64:G66),"-") -> 0.31772327 | H29: =IFERROR('Historical FS'!H26/SUM('Historical FS'!H64:H66),"-") -> 0.34145894 | I29: =IFERROR('Historical FS'!I26/SUM('Historical FS'!I64:I66),"-") -> 0.38962437 | J29: =IFERROR('Historical FS'!J26/SUM('Historical FS'!J64:J66),"-") -> 0.41968318 | ... L29: =IFERROR('Historical FS'!L26/SUM('Historical FS'!L64:L66),"-") -> 0.37710606 | N29: =IFERROR(AVERAGE(C29:L29),"-") -> 0.3369927 | O29: =IFERROR(MEDIAN(C29:L29),"-") -> 0.3295911
B30: Retained Earning % | C30: ='Historical FS'!C58 -> 0.58867225 | D30: ='Historical FS'!D58 -> 0.58952135 | E30: ='Historical FS'!E58 -> 0.40947034 | F30: ='Historical FS'!F58 -> 0.40152498 | G30: ='Historical FS'!G58 -> 0.55363904 | H30: ='Historical FS'!H58 -> 0.4094836 | I30: ='Historical FS'!I58 -> 0.41264337 | J30: ='Historical FS'!J58 -> 0.41640949 | ... L30: ='Historical FS'!L58 -> 0.33354019 | N30: =IFERROR(AVERAGE(C30:L30),"-") -> 0.43890131 | O30: =IFERROR(MEDIAN(C30:L30),"-") -> 0.41106348
B31: Return on Equity % | C31: =IFERROR('Historical FS'!C47/SUM('Historical FS'!C64:C65),"-") -> 0.21846657 | D31: =IFERROR('Historical FS'!D47/SUM('Historical FS'!D64:D65),"-") -> 0.20806877 | E31: =IFERROR('Historical FS'!E47/SUM('Historical FS'!E64:E65),"-") -> 0.24689247 | F31: =IFERROR('Historical FS'!F47/SUM('Historical FS'!F64:F65),"-") -> 0.23726674 | G31: =IFERROR('Historical FS'!G47/SUM('Historical FS'!G64:G65),"-") -> 0.2542246 | H31: =IFERROR('Historical FS'!H47/SUM('Historical FS'!H64:H65),"-") -> 0.25439091 | I31: =IFERROR('Historical FS'!I47/SUM('Historical FS'!I64:I65),"-") -> 0.29390843 | J31: =IFERROR('Historical FS'!J47/SUM('Historical FS'!J64:J65),"-") -> 0.31970507 | ... L31: =IFERROR('Historical FS'!L47/SUM('Historical FS'!L64:L65),"-") -> 0.2791751 | N31: =IFERROR(AVERAGE(C31:L31),"-") -> 0.26099787 | O31: =IFERROR(MEDIAN(C31:L31),"-") -> 0.25430775
B32: Self Sustained Growth Rate | C32: =IFERROR(C31*C30,"-") -> 0.12860521 | D32: =IFERROR(D31*D30,"-") -> 0.12266098 | E32: =IFERROR(E31*E30,"-") -> 0.10109514 | F32: =IFERROR(F31*F30,"-") -> 0.095268523 | G32: =IFERROR(G31*G30,"-") -> 0.14074866 | H32: =IFERROR(H31*H30,"-") -> 0.1041689 | I32: =IFERROR(I31*I30,"-") -> 0.12127936 | J32: =IFERROR(J31*J30,"-") -> 0.13312822 | ... L32: =IFERROR(L31*L30,"-") -> 0.093116116 | N32: =IFERROR(AVERAGE(C32:L32),"-") -> 0.11217226 | O32: =IFERROR(MEDIAN(C32:L32),"-") -> 0.11272413
B33: Interest Coverage Ratio | C33: =IFERROR('Historical FS'!C26/'Historical FS'!C38,"-") -> - | D33: =IFERROR('Historical FS'!D26/'Historical FS'!D38,"-") -> - | E33: =IFERROR('Historical FS'!E26/'Historical FS'!E38,"-") -> - | F33: =IFERROR('Historical FS'!F26/'Historical FS'!F38,"-") -> - | G33: =IFERROR('Historical FS'!G26/'Historical FS'!G38,"-") -> 130.98235 | H33: =IFERROR('Historical FS'!H26/'Historical FS'!H38,"-") -> 143.02051 | I33: =IFERROR('Historical FS'!I26/'Historical FS'!I38,"-") -> 157.455 | J33: =IFERROR('Historical FS'!J26/'Historical FS'!J38,"-") -> 123.69718 | ... L33: =IFERROR('Historical FS'!L26/'Historical FS'!L38,"-") -> 94.317308 | N33: =IFERROR(AVERAGE(C33:L33),"-") -> 121.16206 | O33: =IFERROR(MEDIAN(C33:L33),"-") -> 127.33977
B35: Debtor Turnover ratio | C35: =IFERROR('Historical FS'!C14/'Historical FS'!C75,"-") -> 5.5111209 | D35: =IFERROR('Historical FS'!D14/'Historical FS'!D75,"-") -> 5.557864 | E35: =IFERROR('Historical FS'!E14/'Historical FS'!E75,"-") -> 5.3661543 | F35: =IFERROR('Historical FS'!F14/'Historical FS'!F75,"-") -> 5.5759763 | G35: =IFERROR('Historical FS'!G14/'Historical FS'!G75,"-") -> 4.9110726 | H35: =IFERROR('Historical FS'!H14/'Historical FS'!H75,"-") -> 5.207422 | I35: =IFERROR('Historical FS'!I14/'Historical FS'!I75,"-") -> 5.3591065 | J35: =IFERROR('Historical FS'!J14/'Historical FS'!J75,"-") -> 5.7727738 | ... L35: =IFERROR('Historical FS'!L14/'Historical FS'!L75,"-") -> 5.2310803 | N35: =IFERROR(AVERAGE(C35:L35),"-") -> 5.3582161 | O35: =IFERROR(MEDIAN(C35:L35),"-") -> 5.3626304
B36: Creditor turnover ratio | C36: =IFERROR('Historical FS'!C14/'Historical FS'!C67,"-") -> 4.6758275 | D36: =IFERROR('Historical FS'!D14/'Historical FS'!D67,"-") -> 4.8343922 | E36: =IFERROR('Historical FS'!E14/'Historical FS'!E67,"-") -> 4.8885346 | F36: =IFERROR('Historical FS'!F14/'Historical FS'!F67,"-") -> 4.3244586 | G36: =IFERROR('Historical FS'!G14/'Historical FS'!G67,"-") -> 4.1806419 | H36: =IFERROR('Historical FS'!H14/'Historical FS'!H67,"-") -> 3.8889878 | I36: =IFERROR('Historical FS'!I14/'Historical FS'!I67,"-") -> 3.3878568 | J36: =IFERROR('Historical FS'!J14/'Historical FS'!J67,"-") -> 3.5893128 | ... L36: =IFERROR('Historical FS'!L14/'Historical FS'!L67,"-") -> 3.7254857 | N36: =IFERROR(AVERAGE(C36:L36),"-") -> 4.1254089 | O36: =IFERROR(MEDIAN(C36:L36),"-") -> 4.0348149
B37: Inventory turnover ratio | C37: =IFERROR('Historical FS'!C14/'Historical FS'!C76,"-") -> - | D37: =IFERROR('Historical FS'!D14/'Historical FS'!D76,"-") -> - | E37: =IFERROR('Historical FS'!E14/'Historical FS'!E76,"-") -> - | F37: =IFERROR('Historical FS'!F14/'Historical FS'!F76,"-") -> - | G37: =IFERROR('Historical FS'!G14/'Historical FS'!G76,"-") -> - | H37: =IFERROR('Historical FS'!H14/'Historical FS'!H76,"-") -> - | I37: =IFERROR('Historical FS'!I14/'Historical FS'!I76,"-") -> - | J37: =IFERROR('Historical FS'!J14/'Historical FS'!J76,"-") -> - | ... L37: =IFERROR('Historical FS'!L14/'Historical FS'!L76,"-") -> - | N37: =IFERROR(AVERAGE(C37:L37),"-") -> - | O37: =IFERROR(MEDIAN(C37:L37),"-") -> -
B38: Fixed Assets Turnover ratio | C38: =IFERROR('Historical FS'!C14/'Historical FS'!C70,"-") -> 4.6646496 | D38: =IFERROR('Historical FS'!D14/'Historical FS'!D70,"-") -> 4.8299598 | E38: =IFERROR('Historical FS'!E14/'Historical FS'!E70,"-") -> 5.6085573 | F38: =IFERROR('Historical FS'!F14/'Historical FS'!F70,"-") -> 5.2625716 | G38: =IFERROR('Historical FS'!G14/'Historical FS'!G70,"-") -> 3.8165118 | H38: =IFERROR('Historical FS'!H14/'Historical FS'!H70,"-") -> 3.939306 | I38: =IFERROR('Historical FS'!I14/'Historical FS'!I70,"-") -> 4.7147674 | J38: =IFERROR('Historical FS'!J14/'Historical FS'!J70,"-") -> 5.0219675 | ... L38: =IFERROR('Historical FS'!L14/'Historical FS'!L70,"-") -> 5.2643648 | N38: =IFERROR(AVERAGE(C38:L38),"-") -> 4.8685975 | O38: =IFERROR(MEDIAN(C38:L38),"-") -> 4.9259636
B39: Capital turnover ratio | C39: =IFERROR('Historical FS'!C14/SUM('Historical FS'!C64:C65),"-") -> 1.0112885 | D39: =IFERROR('Historical FS'!D14/SUM('Historical FS'!D64:D65),"-") -> 0.99278073 | E39: =IFERROR('Historical FS'!E14/SUM('Historical FS'!E64:E65),"-") -> 1.0862406 | F39: =IFERROR('Historical FS'!F14/SUM('Historical FS'!F64:F65),"-") -> 1.2729414 | G39: =IFERROR('Historical FS'!G14/SUM('Historical FS'!G64:G65),"-") -> 1.3871811 | H39: =IFERROR('Historical FS'!H14/SUM('Historical FS'!H64:H65),"-") -> 1.3159225 | I39: =IFERROR('Historical FS'!I14/SUM('Historical FS'!I64:I65),"-") -> 1.6143464 | J39: =IFERROR('Historical FS'!J14/SUM('Historical FS'!J64:J65),"-") -> 1.9463312 | ... L39: =IFERROR('Historical FS'!L14/SUM('Historical FS'!L64:L65),"-") -> 1.7010374 | N39: =IFERROR(AVERAGE(C39:L39),"-") -> 1.4072021 | O39: =IFERROR(MEDIAN(C39:L39),"-") -> 1.3515518
B41: Debtor Days | C41: =IFERROR(365/C35,"-") -> 66.229721 | D41: =IFERROR(365/D35,"-") -> 65.672712 | E41: =IFERROR(365/E35,"-") -> 68.018916 | F41: =IFERROR(365/F35,"-") -> 65.459389 | G41: =IFERROR(365/G35,"-") -> 74.321849 | H41: =IFERROR(365/H35,"-") -> 70.092265 | I41: =IFERROR(365/I35,"-") -> 68.108368 | J41: =IFERROR(365/J35,"-") -> 63.227837 | ... L41: =IFERROR(365/L35,"-") -> 69.775262 | N41: =IFERROR(AVERAGE(C41:L41),"-") -> 68.262133 | O41: =IFERROR(MEDIAN(C41:L41),"-") -> 68.063642
B42: Creditor Days | C42: =IFERROR(365/C36,"-") -> 78.06105 | D42: =IFERROR(365/D36,"-") -> 75.500701 | E42: =IFERROR(365/E36,"-") -> 74.664502 | F42: =IFERROR(365/F36,"-") -> 84.403629 | G42: =IFERROR(365/G36,"-") -> 87.307167 | H42: =IFERROR(365/H36,"-") -> 93.854756 | I42: =IFERROR(365/I36,"-") -> 107.73773 | J42: =IFERROR(365/J36,"-") -> 101.69078 | ... L42: =IFERROR(365/L36,"-") -> 97.973802 | N42: =IFERROR(AVERAGE(C42:L42),"-") -> 89.830496 | O42: =IFERROR(MEDIAN(C42:L42),"-") -> 90.580961
B43: Inventory Days | C43: =IFERROR(365/C37,"-") -> - | D43: =IFERROR(365/D37,"-") -> - | E43: =IFERROR(365/E37,"-") -> - | F43: =IFERROR(365/F37,"-") -> - | G43: =IFERROR(365/G37,"-") -> - | H43: =IFERROR(365/H37,"-") -> - | I43: =IFERROR(365/I37,"-") -> - | J43: =IFERROR(365/J37,"-") -> - | ... L43: =IFERROR(365/L37,"-") -> - | N43: =IFERROR(AVERAGE(C43:L43),"-") -> - | O43: =IFERROR(MEDIAN(C43:L43),"-") -> -
B44: Cash Conversion Cycle (CCC) | C44: =IFERROR(SUM(C41,C43)-C42,"-") -> -11.831329 | D44: =IFERROR(SUM(D41,D43)-D42,"-") -> -9.827989 | E44: =IFERROR(SUM(E41,E43)-E42,"-") -> -6.6455858 | F44: =IFERROR(SUM(F41,F43)-F42,"-") -> -18.944239 | G44: =IFERROR(SUM(G41,G43)-G42,"-") -> -12.985318 | H44: =IFERROR(SUM(H41,H43)-H42,"-") -> -23.762491 | I44: =IFERROR(SUM(I41,I43)-I42,"-") -> -39.62936 | J44: =IFERROR(SUM(J41,J43)-J42,"-") -> -38.462938 | ... L44: =IFERROR(SUM(L41,L43)-L42,"-") -> -28.19854 | N44: =IFERROR(AVERAGE(C44:L44),"-") -> -21.568364 | O44: =IFERROR(MEDIAN(C44:L44),"-") -> -21.353365
B46: CFO / Sales | C46: =IFERROR('Historical FS'!C94/'Historical FS'!C14,"-") -> 0.16059961 | D46: =IFERROR('Historical FS'!D94/'Historical FS'!D14,"-") -> 0.16837509 | E46: =IFERROR('Historical FS'!E94/'Historical FS'!E14,"-") -> 0.18743087 | F46: =IFERROR('Historical FS'!F94/'Historical FS'!F14,"-") -> 0.17951013 | G46: =IFERROR('Historical FS'!G94/'Historical FS'!G14,"-") -> 0.18727627 | H46: =IFERROR('Historical FS'!H94/'Historical FS'!H14,"-") -> 0.23114898 | I46: =IFERROR('Historical FS'!I94/'Historical FS'!I14,"-") -> 0.19635649 | J46: =IFERROR('Historical FS'!J94/'Historical FS'!J14,"-") -> 0.15307937 | ... L46: =IFERROR('Historical FS'!L94/'Historical FS'!L14,"-") -> 0.21899503 | N46: =IFERROR(AVERAGE(C46:L46),"-") -> 0.18468247 | O46: =IFERROR(MEDIAN(C46:L46),"-") -> 0.1833932
B47: CFO / Total Assets | C47: =IFERROR('Historical FS'!C94/'Historical FS'!C81,"-") -> 0.13353218 | D47: =IFERROR('Historical FS'!D94/'Historical FS'!D81,"-") -> 0.13868043 | E47: =IFERROR('Historical FS'!E94/'Historical FS'!E81,"-") -> 0.16658055 | F47: =IFERROR('Historical FS'!F94/'Historical FS'!F81,"-") -> 0.17653986 | G47: =IFERROR('Historical FS'!G94/'Historical FS'!G81,"-") -> 0.18521786 | H47: =IFERROR('Historical FS'!H94/'Historical FS'!H81,"-") -> 0.21601511 | I47: =IFERROR('Historical FS'!I94/'Historical FS'!I81,"-") -> 0.20461925 | J47: =IFERROR('Historical FS'!J94/'Historical FS'!J81,"-") -> 0.18031879 | ... L47: =IFERROR('Historical FS'!L94/'Historical FS'!L81,"-") -> 0.2415102 | N47: =IFERROR(AVERAGE(C47:L47),"-") -> 0.18265466 | O47: =IFERROR(MEDIAN(C47:L47),"-") -> 0.18192556
B48: CFO / Total Debt | C48: =IFERROR('Historical FS'!C94/SUM('Historical FS'!C66+'Historical FS'!C67),"-") -> 0.75093605 | D48: =IFERROR('Historical FS'!D94/SUM('Historical FS'!D66+'Historical FS'!D67),"-") -> 0.81399125 | E48: =IFERROR('Historical FS'!E94/SUM('Historical FS'!E66+'Historical FS'!E67),"-") -> 0.9162623 | F48: =IFERROR('Historical FS'!F94/SUM('Historical FS'!F66+'Historical FS'!F67),"-") -> 0.77628413 | G48: =IFERROR('Historical FS'!G94/SUM('Historical FS'!G66+'Historical FS'!G67),"-") -> 0.64527514 | H48: =IFERROR('Historical FS'!H94/SUM('Historical FS'!H66+'Historical FS'!H67),"-") -> 0.74531451 | I48: =IFERROR('Historical FS'!I94/SUM('Historical FS'!I66+'Historical FS'!I67),"-") -> 0.57722516 | J48: =IFERROR('Historical FS'!J94/SUM('Historical FS'!J66+'Historical FS'!J67),"-") -> 0.45674846 | ... L48: =IFERROR('Historical FS'!L94/SUM('Historical FS'!L66+'Historical FS'!L67),"-") -> 0.68672682 | N48: =IFERROR(AVERAGE(C48:L48),"-") -> 0.68807044 | O48: =IFERROR(MEDIAN(C48:L48),"-") -> 0.71602066

Sheet Common size 
B4: ='Data Sheet'!$B$1 -> INFOSYS LTD
B5: ( NSE: INFY | BSE: 500209)
B6: 1250
B7: 52 Week (High 1728 & Low 1215)
B10: ="Common Size Statements" -> Common Size Statements
B11: Particulars | C11: ='Data Sheet'!B16 -> 42460 | D11: ='Data Sheet'!C16 -> 42825 | E11: ='Data Sheet'!D16 -> 43190 | F11: ='Data Sheet'!E16 -> 43555 | G11: ='Data Sheet'!F16 -> 43921 | H11: ='Data Sheet'!G16 -> 44286 | I11: ='Data Sheet'!H16 -> 44651 | J11: ='Data Sheet'!I16 -> 45016 | ... L11: ='Data Sheet'!K16 -> 45747
A13: # | B13: Income Statement
B14: ='Data Sheet'!A17 -> Sales | C14: =IFERROR('Data Sheet'!B17/'Data Sheet'!B$17,"-") -> 1 | D14: =IFERROR('Data Sheet'!C17/'Data Sheet'!C$17,"-") -> 1 | E14: =IFERROR('Data Sheet'!D17/'Data Sheet'!D$17,"-") -> 1 | F14: =IFERROR('Data Sheet'!E17/'Data Sheet'!E$17,"-") -> 1 | G14: =IFERROR('Data Sheet'!F17/'Data Sheet'!F$17,"-") -> 1 | H14: =IFERROR('Data Sheet'!G17/'Data Sheet'!G$17,"-") -> 1 | I14: =IFERROR('Data Sheet'!H17/'Data Sheet'!H$17,"-") -> 1 | J14: =IFERROR('Data Sheet'!I17/'Data Sheet'!I$17,"-") -> 1 | ... L14: =IFERROR('Data Sheet'!K17/'Data Sheet'!K$17,"-") -> 1
B15: ='Data Sheet'!A18 -> Raw Material Cost | C15: =IFERROR('Data Sheet'!B18/'Data Sheet'!B$17,"-") -> 0 | D15: =IFERROR('Data Sheet'!C18/'Data Sheet'!C$17,"-") -> 0 | E15: =IFERROR('Data Sheet'!D18/'Data Sheet'!D$17,"-") -> 0 | F15: =IFERROR('Data Sheet'!E18/'Data Sheet'!E$17,"-") -> 0 | G15: =IFERROR('Data Sheet'!F18/'Data Sheet'!F$17,"-") -> 0 | H15: =IFERROR('Data Sheet'!G18/'Data Sheet'!G$17,"-") -> 0 | I15: =IFERROR('Data Sheet'!H18/'Data Sheet'!H$17,"-") -> 0 | J15: =IFERROR('Data Sheet'!I18/'Data Sheet'!I$17,"-") -> 0 | ... L15: =IFERROR('Data Sheet'!K18/'Data Sheet'!K$17,"-") -> 0
B16: ='Data Sheet'!A19 -> Change in Inventory | C16: =IFERROR('Data Sheet'!B19/'Data Sheet'!B$17,"-") -> 0 | D16: =IFERROR('Data Sheet'!C19/'Data Sheet'!C$17,"-") -> 0 | E16: =IFERROR('Data Sheet'!D19/'Data Sheet'!D$17,"-") -> 0 | F16: =IFERROR('Data Sheet'!E19/'Data Sheet'!E$17,"-") -> 0 | G16: =IFERROR('Data Sheet'!F19/'Data Sheet'!F$17,"-") -> 0 | H16: =IFERROR('Data Sheet'!G19/'Data Sheet'!G$17,"-") -> 0 | I16: =IFERROR('Data Sheet'!H19/'Data Sheet'!H$17,"-") -> 0 | J16: =IFERROR('Data Sheet'!I19/'Data Sheet'!I$17,"-") -> 0 | ... L16: =IFERROR('Data Sheet'!K19/'Data Sheet'!K$17,"-") -> 0
B17: ='Data Sheet'!A20 -> Power and Fuel | C17: =IFERROR('Data Sheet'!B20/'Data Sheet'!B$17,"-") -> 0.0034752807 | D17: =IFERROR('Data Sheet'!C20/'Data Sheet'!C$17,"-") -> 0.0033292448 | E17: =IFERROR('Data Sheet'!D20/'Data Sheet'!D$17,"-") -> 0.0029352542 | F17: =IFERROR('Data Sheet'!E20/'Data Sheet'!E$17,"-") -> 0.0026731176 | G17: =IFERROR('Data Sheet'!F20/'Data Sheet'!F$17,"-") -> 0.0025222764 | H17: =IFERROR('Data Sheet'!G20/'Data Sheet'!G$17,"-") -> 0.0014232821 | I17: =IFERROR('Data Sheet'!H20/'Data Sheet'!H$17,"-") -> 0.0010851604 | J17: =IFERROR('Data Sheet'!I20/'Data Sheet'!I$17,"-") -> 0.0011991797 | ... L17: =IFERROR('Data Sheet'!K20/'Data Sheet'!K$17,"-") -> 0.0013620468
B18: ='Data Sheet'!A21 -> Other Mfr. Exp | C18: =IFERROR('Data Sheet'!B21/'Data Sheet'!B$17,"-") -> 0.093848593 | D18: =IFERROR('Data Sheet'!C21/'Data Sheet'!C$17,"-") -> 0.098008294 | E18: =IFERROR('Data Sheet'!D21/'Data Sheet'!D$17,"-") -> 0.10331528 | F18: =IFERROR('Data Sheet'!E21/'Data Sheet'!E$17,"-") -> 0.11977018 | G18: =IFERROR('Data Sheet'!F21/'Data Sheet'!F$17,"-") -> 0.12210461 | H18: =IFERROR('Data Sheet'!G21/'Data Sheet'!G$17,"-") -> 0.12739868 | I18: =IFERROR('Data Sheet'!H21/'Data Sheet'!H$17,"-") -> 0.17009068 | J18: =IFERROR('Data Sheet'!I21/'Data Sheet'!I$17,"-") -> 0.1794 | ... L18: =IFERROR('Data Sheet'!K21/'Data Sheet'!K$17,"-") -> 0.18648383
B19: ='Data Sheet'!A22 -> Employee Cost | C19: =IFERROR('Data Sheet'!B22/'Data Sheet'!B$17,"-") -> 0.5511603 | D19: =IFERROR('Data Sheet'!C22/'Data Sheet'!C$17,"-") -> 0.55004089 | E19: =IFERROR('Data Sheet'!D22/'Data Sheet'!D$17,"-") -> 0.55162928 | F19: =IFERROR('Data Sheet'!E22/'Data Sheet'!E$17,"-") -> 0.54820683 | G19: =IFERROR('Data Sheet'!F22/'Data Sheet'!F$17,"-") -> 0.56057318 | H19: =IFERROR('Data Sheet'!G22/'Data Sheet'!G$17,"-") -> 0.5528605 | I19: =IFERROR('Data Sheet'!H22/'Data Sheet'!H$17,"-") -> 0.52611373 | J19: =IFERROR('Data Sheet'!I22/'Data Sheet'!I$17,"-") -> 0.53400288 | ... L19: =IFERROR('Data Sheet'!K22/'Data Sheet'!K$17,"-") -> 0.5274434
B20: ='Data Sheet'!A23 -> Selling and admin | C20: =IFERROR('Data Sheet'!B23/'Data Sheet'!B$17,"-") -> 0.07112314 | D20: =IFERROR('Data Sheet'!C23/'Data Sheet'!C$17,"-") -> 0.066935343 | E20: =IFERROR('Data Sheet'!D23/'Data Sheet'!D$17,"-") -> 0.065015173 | F20: =IFERROR('Data Sheet'!E23/'Data Sheet'!E$17,"-") -> 0.067166616 | G20: =IFERROR('Data Sheet'!F23/'Data Sheet'!F$17,"-") -> 0.059201903 | H20: =IFERROR('Data Sheet'!G23/'Data Sheet'!G$17,"-") -> 0.031789951 | I20: =IFERROR('Data Sheet'!H23/'Data Sheet'!H$17,"-") -> 0.035391028 | J20: =IFERROR('Data Sheet'!I23/'Data Sheet'!I$17,"-") -> 0.03611166 | ... L20: =IFERROR('Data Sheet'!K23/'Data Sheet'!K$17,"-") -> 0.037051353
B21: ='Data Sheet'!A24 -> Other Expenses | C21: =IFERROR('Data Sheet'!B24/'Data Sheet'!B$17,"-") -> 0.0068704857 | D21: =IFERROR('Data Sheet'!C24/'Data Sheet'!C$17,"-") -> 0.01003154 | E21: =IFERROR('Data Sheet'!D24/'Data Sheet'!D$17,"-") -> 0.01020958 | F21: =IFERROR('Data Sheet'!E24/'Data Sheet'!E$17,"-") -> 0.018215906 | G21: =IFERROR('Data Sheet'!F24/'Data Sheet'!F$17,"-") -> 0.010342435 | H21: =IFERROR('Data Sheet'!G24/'Data Sheet'!G$17,"-") -> 0.0089477665 | I21: =IFERROR('Data Sheet'!H24/'Data Sheet'!H$17,"-") -> 0.0084346561 | J21: =IFERROR('Data Sheet'!I24/'Data Sheet'!I$17,"-") -> 0.0099272997 | ... L21: =IFERROR('Data Sheet'!K24/'Data Sheet'!K$17,"-") -> 0.0069329407
B22: ='Data Sheet'!A25 -> Other Income | C22: =IFERROR('Data Sheet'!B25/'Data Sheet'!B$17,"-") -> 0.049967169 | D22: =IFERROR('Data Sheet'!C25/'Data Sheet'!C$17,"-") -> 0.04453595 | E22: =IFERROR('Data Sheet'!D25/'Data Sheet'!D$17,"-") -> 0.046949888 | F22: =IFERROR('Data Sheet'!E25/'Data Sheet'!E$17,"-") -> 0.034859389 | G22: =IFERROR('Data Sheet'!F25/'Data Sheet'!F$17,"-") -> 0.030873104 | H22: =IFERROR('Data Sheet'!G25/'Data Sheet'!G$17,"-") -> 0.021906601 | I22: =IFERROR('Data Sheet'!H25/'Data Sheet'!H$17,"-") -> 0.018866994 | J22: =IFERROR('Data Sheet'!I25/'Data Sheet'!I$17,"-") -> 0.01840332 | ... L22: =IFERROR('Data Sheet'!K25/'Data Sheet'!K$17,"-") -> 0.022087245
B23: ='Data Sheet'!A26 -> Depreciation | C23: =IFERROR('Data Sheet'!B26/'Data Sheet'!B$17,"-") -> 0.023366058 | D23: =IFERROR('Data Sheet'!C26/'Data Sheet'!C$17,"-") -> 0.024867122 | E23: =IFERROR('Data Sheet'!D26/'Data Sheet'!D$17,"-") -> 0.026417288 | F23: =IFERROR('Data Sheet'!E26/'Data Sheet'!E$17,"-") -> 0.024324161 | G23: =IFERROR('Data Sheet'!F26/'Data Sheet'!F$17,"-") -> 0.031864392 | H23: =IFERROR('Data Sheet'!G26/'Data Sheet'!G$17,"-") -> 0.032516522 | I23: =IFERROR('Data Sheet'!H26/'Data Sheet'!H$17,"-") -> 0.028575891 | J23: =IFERROR('Data Sheet'!I26/'Data Sheet'!I$17,"-") -> 0.028787125 | ... L23: =IFERROR('Data Sheet'!K26/'Data Sheet'!K$17,"-") -> 0.029523284
B24: ='Data Sheet'!A27 -> Interest | C24: =IFERROR('Data Sheet'!B27/'Data Sheet'!B$17,"-") -> 0 | D24: =IFERROR('Data Sheet'!C27/'Data Sheet'!C$17,"-") -> 0 | E24: =IFERROR('Data Sheet'!D27/'Data Sheet'!D$17,"-") -> 0 | F24: =IFERROR('Data Sheet'!E27/'Data Sheet'!E$17,"-") -> 0 | G24: =IFERROR('Data Sheet'!F27/'Data Sheet'!F$17,"-") -> 0.0018724323 | H24: =IFERROR('Data Sheet'!G27/'Data Sheet'!G$17,"-") -> 0.0019408392 | I24: =IFERROR('Data Sheet'!H27/'Data Sheet'!H$17,"-") -> 0.0016441825 | J24: =IFERROR('Data Sheet'!I27/'Data Sheet'!I$17,"-") -> 0.0019350399 | ... L24: =IFERROR('Data Sheet'!K27/'Data Sheet'!K$17,"-") -> 0.0025523038
B25: ='Data Sheet'!A28 -> Profit before tax | C25: =IFERROR('Data Sheet'!B28/'Data Sheet'!B$17,"-") -> 0.30012332 | D25: =IFERROR('Data Sheet'!C28/'Data Sheet'!C$17,"-") -> 0.29132352 | E25: =IFERROR('Data Sheet'!D28/'Data Sheet'!D$17,"-") -> 0.28742804 | F25: =IFERROR('Data Sheet'!E28/'Data Sheet'!E$17,"-") -> 0.25450257 | G25: =IFERROR('Data Sheet'!F28/'Data Sheet'!F$17,"-") -> 0.24239187 | H25: =IFERROR('Data Sheet'!G28/'Data Sheet'!G$17,"-") -> 0.26502906 | I25: =IFERROR('Data Sheet'!H28/'Data Sheet'!H$17,"-") -> 0.24753167 | J25: =IFERROR('Data Sheet'!I28/'Data Sheet'!I$17,"-") -> 0.22704014 | ... L25: =IFERROR('Data Sheet'!K28/'Data Sheet'!K$17,"-") -> 0.23073808
... B29: ='Data Sheet'!A32 -> EBITDA | C29: =IFERROR('Data Sheet'!B32/'Data Sheet'!B$17,"-") -> 0.2735222 | D29: =IFERROR('Data Sheet'!C32/'Data Sheet'!C$17,"-") -> 0.27165469 | E29: =IFERROR('Data Sheet'!D32/'Data Sheet'!D$17,"-") -> 0.26689544 | F29: =IFERROR('Data Sheet'!E32/'Data Sheet'!E$17,"-") -> 0.24396734 | G29: =IFERROR('Data Sheet'!F32/'Data Sheet'!F$17,"-") -> 0.24525559 | H29: =IFERROR('Data Sheet'!G32/'Data Sheet'!G$17,"-") -> 0.27757982 | I29: =IFERROR('Data Sheet'!H32/'Data Sheet'!H$17,"-") -> 0.25888475 | J29: =IFERROR('Data Sheet'!I32/'Data Sheet'!I$17,"-") -> 0.23935898 | ... L29: =IFERROR('Data Sheet'!K32/'Data Sheet'!K$17,"-") -> 0.24072642
A31: # | B31: Balance Sheet
B32: ='Data Sheet'!A61 & " Liabilities " -> Total Liabilities | C32: =IFERROR('Data Sheet'!B61/'Data Sheet'!B61,"-") -> 1 | D32: =IFERROR('Data Sheet'!C61/'Data Sheet'!C61,"-") -> 1 | E32: =IFERROR('Data Sheet'!D61/'Data Sheet'!D61,"-") -> 1 | F32: =IFERROR('Data Sheet'!E61/'Data Sheet'!E61,"-") -> 1 | G32: =IFERROR('Data Sheet'!F61/'Data Sheet'!F61,"-") -> 1 | H32: =IFERROR('Data Sheet'!G61/'Data Sheet'!G61,"-") -> 1 | I32: =IFERROR('Data Sheet'!H61/'Data Sheet'!H61,"-") -> 1 | J32: =IFERROR('Data Sheet'!I61/'Data Sheet'!I61,"-") -> 1 | ... L32: =IFERROR('Data Sheet'!K61/'Data Sheet'!K61,"-") -> 1
B33: ='Data Sheet'!A57 -> Equity Share Capital | C33: =IFERROR('Data Sheet'!B57/'Data Sheet'!B$61,"-") -> 0.015233428 | D33: =IFERROR('Data Sheet'!C57/'Data Sheet'!C$61,"-") -> 0.013758599 | E33: =IFERROR('Data Sheet'!D57/'Data Sheet'!D$61,"-") -> 0.013711578 | F33: =IFERROR('Data Sheet'!E57/'Data Sheet'!E$61,"-") -> 0.025813052 | G33: =IFERROR('Data Sheet'!F57/'Data Sheet'!F$61,"-") -> 0.023115468 | H33: =IFERROR('Data Sheet'!G57/'Data Sheet'!G$61,"-") -> 0.019756118 | I33: =IFERROR('Data Sheet'!H57/'Data Sheet'!H$61,"-") -> 0.017973254 | J33: =IFERROR('Data Sheet'!I57/'Data Sheet'!I$61,"-") -> 0.01660567 | ... L33: =IFERROR('Data Sheet'!K57/'Data Sheet'!K$61,"-") -> 0.014026185
B34: ='Data Sheet'!A58 -> Reserves | C34: =IFERROR('Data Sheet'!B58/'Data Sheet'!B$61,"-") -> 0.80694559 | D34: =IFERROR('Data Sheet'!C58/'Data Sheet'!C$61,"-") -> 0.8158705 | E34: =IFERROR('Data Sheet'!D58/'Data Sheet'!D$61,"-") -> 0.80448399 | F34: =IFERROR('Data Sheet'!E58/'Data Sheet'!E$61,"-") -> 0.74677039 | G34: =IFERROR('Data Sheet'!F58/'Data Sheet'!F$61,"-") -> 0.68984749 | H34: =IFERROR('Data Sheet'!G58/'Data Sheet'!G$61,"-") -> 0.69041307 | I34: =IFERROR('Data Sheet'!H58/'Data Sheet'!H$61,"-") -> 0.627539 | J34: =IFERROR('Data Sheet'!I58/'Data Sheet'!I$61,"-") -> 0.58860638 | ... L34: =IFERROR('Data Sheet'!K58/'Data Sheet'!K$61,"-") -> 0.63429074
B35: ='Data Sheet'!A59 -> Borrowings | C35: =IFERROR('Data Sheet'!B59/'Data Sheet'!B$61,"-") -> 0 | D35: =IFERROR('Data Sheet'!C59/'Data Sheet'!C$61,"-") -> 0 | E35: =IFERROR('Data Sheet'!D59/'Data Sheet'!D$61,"-") -> 0 | F35: =IFERROR('Data Sheet'!E59/'Data Sheet'!E$61,"-") -> 0 | G35: =IFERROR('Data Sheet'!F59/'Data Sheet'!F$61,"-") -> 0.05046841 | H35: =IFERROR('Data Sheet'!G59/'Data Sheet'!G$61,"-") -> 0.049529816 | I35: =IFERROR('Data Sheet'!H59/'Data Sheet'!H$61,"-") -> 0.046894945 | J35: =IFERROR('Data Sheet'!I59/'Data Sheet'!I$61,"-") -> 0.066607275 | ... L35: =IFERROR('Data Sheet'!K59/'Data Sheet'!K$61,"-") -> 0.055664941
B36: ='Data Sheet'!A60 -> Other Liabilities | C36: =IFERROR('Data Sheet'!B60/'Data Sheet'!B$61,"-") -> 0.17782098 | D36: =IFERROR('Data Sheet'!C60/'Data Sheet'!C$61,"-") -> 0.1703709 | E36: =IFERROR('Data Sheet'!D60/'Data Sheet'!D$61,"-") -> 0.18180443 | F36: =IFERROR('Data Sheet'!E60/'Data Sheet'!E$61,"-") -> 0.22741655 | G36: =IFERROR('Data Sheet'!F60/'Data Sheet'!F$61,"-") -> 0.23656863 | H36: =IFERROR('Data Sheet'!G60/'Data Sheet'!G$61,"-") -> 0.24030099 | I36: =IFERROR('Data Sheet'!H60/'Data Sheet'!H$61,"-") -> 0.3075928 | J36: =IFERROR('Data Sheet'!I60/'Data Sheet'!I$61,"-") -> 0.32818068 | ... L36: =IFERROR('Data Sheet'!K60/'Data Sheet'!K$61,"-") -> 0.29601813
B38: ='Data Sheet'!A66 & " Assets " -> Total Assets | C38: =IFERROR('Data Sheet'!B66/'Data Sheet'!B66,"-") -> 1 | D38: =IFERROR('Data Sheet'!C66/'Data Sheet'!C66,"-") -> 1 | E38: =IFERROR('Data Sheet'!D66/'Data Sheet'!D66,"-") -> 1 | F38: =IFERROR('Data Sheet'!E66/'Data Sheet'!E66,"-") -> 1 | G38: =IFERROR('Data Sheet'!F66/'Data Sheet'!F66,"-") -> 1 | H38: =IFERROR('Data Sheet'!G66/'Data Sheet'!G66,"-") -> 1 | I38: =IFERROR('Data Sheet'!H66/'Data Sheet'!H66,"-") -> 1 | J38: =IFERROR('Data Sheet'!I66/'Data Sheet'!I66,"-") -> 1 | ... L38: =IFERROR('Data Sheet'!K66/'Data Sheet'!K66,"-") -> 1
B39: ="Fixed Assets" & " - " & 'Data Sheet'!A62 -> Fixed Assets - Net Block | C39: =IFERROR('Data Sheet'!B62/'Data Sheet'!B$66,"-") -> 0.17824709 | D39: =IFERROR('Data Sheet'!C62/'Data Sheet'!C$66,"-") -> 0.17052725 | E39: =IFERROR('Data Sheet'!D62/'Data Sheet'!D$66,"-") -> 0.1584645 | F39: =IFERROR('Data Sheet'!E62/'Data Sheet'!E$66,"-") -> 0.18687698 | G39: =IFERROR('Data Sheet'!F62/'Data Sheet'!F$66,"-") -> 0.25913943 | H39: =IFERROR('Data Sheet'!G62/'Data Sheet'!G$66,"-") -> 0.23723154 | I39: =IFERROR('Data Sheet'!H62/'Data Sheet'!H$66,"-") -> 0.22102477 | J39: =IFERROR('Data Sheet'!I62/'Data Sheet'!I$66,"-") -> 0.23455809 | ... L39: =IFERROR('Data Sheet'!K62/'Data Sheet'!K$66,"-") -> 0.20948611
B40: ='Data Sheet'!A63 -> Capital Work in Progress | C40: =IFERROR('Data Sheet'!B63/'Data Sheet'!B$66,"-") -> 0.012783296 | D40: =IFERROR('Data Sheet'!C63/'Data Sheet'!C$66,"-") -> 0.01641651 | E40: =IFERROR('Data Sheet'!D63/'Data Sheet'!D$66,"-") -> 0.020239701 | F40: =IFERROR('Data Sheet'!E63/'Data Sheet'!E$66,"-") -> 0.016510837 | G40: =IFERROR('Data Sheet'!F63/'Data Sheet'!F$66,"-") -> 0.010392157 | H40: =IFERROR('Data Sheet'!G63/'Data Sheet'!G$66,"-") -> 0.0085758667 | I40: =IFERROR('Data Sheet'!H63/'Data Sheet'!H$66,"-") -> 0.0035638102 | J40: =IFERROR('Data Sheet'!I63/'Data Sheet'!I$66,"-") -> 0.0023114707 | ... L40: =IFERROR('Data Sheet'!K63/'Data Sheet'!K$66,"-") -> 0.0055076288
B41: ='Data Sheet'!A64 -> Investments | C41: =IFERROR('Data Sheet'!B64/'Data Sheet'!B$66,"-") -> 0.025193747 | D41: =IFERROR('Data Sheet'!C64/'Data Sheet'!C$66,"-") -> 0.19751527 | E41: =IFERROR('Data Sheet'!D64/'Data Sheet'!D$66,"-") -> 0.15328486 | F41: =IFERROR('Data Sheet'!E64/'Data Sheet'!E$66,"-") -> 0.13395427 | G41: =IFERROR('Data Sheet'!F64/'Data Sheet'!F$66,"-") -> 0.09577342 | H41: =IFERROR('Data Sheet'!G64/'Data Sheet'!G$66,"-") -> 0.13212602 | I41: =IFERROR('Data Sheet'!H64/'Data Sheet'!H$66,"-") -> 0.17411269 | J41: =IFERROR('Data Sheet'!I64/'Data Sheet'!I$66,"-") -> 0.15632926 | ... L41: =IFERROR('Data Sheet'!K64/'Data Sheet'!K$66,"-") -> 0.15928144
B42: ='Data Sheet'!A65 -> Other Assets | C42: =IFERROR('Data Sheet'!B74/'Data Sheet'!B$66,"-") -> 0.19751525 | D42: =IFERROR('Data Sheet'!C74/'Data Sheet'!C$66,"-") -> 0.19524222 | E42: =IFERROR('Data Sheet'!D74/'Data Sheet'!D$66,"-") -> 0.25263078 | F42: =IFERROR('Data Sheet'!E74/'Data Sheet'!E$66,"-") -> 0.2535151 | G42: =IFERROR('Data Sheet'!F74/'Data Sheet'!F$66,"-") -> 0.2301634 | H42: =IFERROR('Data Sheet'!G74/'Data Sheet'!G$66,"-") -> 0.21273172 | I42: =IFERROR('Data Sheet'!H74/'Data Sheet'!H$66,"-") -> 0.25716831 | J42: =IFERROR('Data Sheet'!I74/'Data Sheet'!I$66,"-") -> 0.30504992 | ... L42: =IFERROR('Data Sheet'!K74/'Data Sheet'!K$66,"-") -> 0.2494401
B43: ='Data Sheet'!A67 -> Receivables | C43: =IFERROR('Data Sheet'!B67/'Data Sheet'!B$66,"-") -> 0.15086953 | D43: =IFERROR('Data Sheet'!C67/'Data Sheet'!C$66,"-") -> 0.14819358 | E43: =IFERROR('Data Sheet'!D67/'Data Sheet'!D$66,"-") -> 0.16562276 | F43: =IFERROR('Data Sheet'!E67/'Data Sheet'!E$66,"-") -> 0.17637333 | G43: =IFERROR('Data Sheet'!F67/'Data Sheet'!F$66,"-") -> 0.20138344 | H43: =IFERROR('Data Sheet'!G67/'Data Sheet'!G$66,"-") -> 0.17946071 | I43: =IFERROR('Data Sheet'!H67/'Data Sheet'!H$66,"-") -> 0.19445039 | J43: =IFERROR('Data Sheet'!I67/'Data Sheet'!I$66,"-") -> 0.20405149 | ... L43: =IFERROR('Data Sheet'!K67/'Data Sheet'!K$66,"-") -> 0.21081904
